<robot name="onshape">
<link name="body_1">
<inertial>
<origin xyz="0 0 0" rpy="0 0 0" />
<mass value="1e-9" />
<inertia ixx="0" ixy="0" ixz="0" iyy="0" iyz="0" izz="0" />
</inertial>
</link>
<link name="body_1_0_body">
<visual>
<geometry>
<mesh filename="package://body.stl"/>
</geometry>
<material name="body_1_0_body_material">
<color rgba="0.972549 0.529412 0.00392157 1.0"/>
</material>
</visual>
<collision>
<geometry>
<mesh filename="package://body.stl"/>
</geometry>
<material name="body_1_0_body_material">
<color rgba="0.972549 0.529412 0.00392157 1.0"/>
</material>
</collision>
<inertial>
<origin xyz="1.71078e-19 5.13234e-19 0.00115" rpy="0 0 0"/>
<mass value="0.00508653"/>
<inertia ixx="8.92046e-07" ixy="0"  ixz="0" iyy="8.92046e-07" iyz="0" izz="1.77961e-06" />
</inertial>
</link>
<joint name="body_1_body_1_0_body_fixing" type="fixed">
<origin xyz="0 0 0" rpy="0 -0 0" />
<parent link="body_1" />
<child link="body_1_0_body" />
<axis xyz="0 0 0"/>
</joint>

<link name="body_1_1_horn">
<visual>
<geometry>
<mesh filename="package://horn.stl"/>
</geometry>
<material name="body_1_1_horn_material">
<color rgba="0.917647 0.917647 0.917647 1.0"/>
</material>
</visual>
<collision>
<geometry>
<mesh filename="package://horn.stl"/>
</geometry>
<material name="body_1_1_horn_material">
<color rgba="0.917647 0.917647 0.917647 1.0"/>
</material>
</collision>
<inertial>
<origin xyz="-2.29324e-19 -1.05216e-18 -0.0134483" rpy="0 0 0"/>
<mass value="0.000575062"/>
<inertia ixx="1.30173e-08" ixy="0"  ixz="0" iyy="1.30173e-08" iyz="0" izz="2.51949e-08" />
</inertial>
</link>
<joint name="body_1_body_1_1_horn_fixing" type="fixed">
<origin xyz="3.46945e-18 -0.0485 0.0143" rpy="0 -0 1.49355" />
<parent link="body_1" />
<child link="body_1_1_horn" />
<axis xyz="0 0 0"/>
</joint>

<link name="body_1_2_motor">
<visual>
<geometry>
<mesh filename="package://motor.stl"/>
</geometry>
<material name="body_1_2_motor_material">
<color rgba="0.470588 0.470588 0.470588 1.0"/>
</material>
</visual>
<collision>
<geometry>
<mesh filename="package://motor.stl"/>
</geometry>
<material name="body_1_2_motor_material">
<color rgba="0.470588 0.470588 0.470588 1.0"/>
</material>
</collision>
<inertial>
<origin xyz="2.21444e-09 -0.00683721 0.000497669" rpy="0 0 0"/>
<mass value="0.0171001"/>
<inertia ixx="2.29537e-06" ixy="-5.64962e-13"  ixz="-2.154e-13" iyy="1.52616e-06" iyz="-6.36265e-08" izz="2.01963e-06" />
</inertial>
</link>
<joint name="body_1_body_1_2_motor_fixing" type="fixed">
<origin xyz="0.0485 1.04083e-17 0.0143" rpy="1.68501e-23 -2.67145e-23 -1.5708" />
<parent link="body_1" />
<child link="body_1_2_motor" />
<axis xyz="0 0 0"/>
</joint>

<link name="body_1_3_motor">
<visual>
<geometry>
<mesh filename="package://motor.stl"/>
</geometry>
<material name="body_1_3_motor_material">
<color rgba="0.470588 0.470588 0.470588 1.0"/>
</material>
</visual>
<collision>
<geometry>
<mesh filename="package://motor.stl"/>
</geometry>
<material name="body_1_3_motor_material">
<color rgba="0.470588 0.470588 0.470588 1.0"/>
</material>
</collision>
<inertial>
<origin xyz="2.21444e-09 -0.00683721 0.000497669" rpy="0 0 0"/>
<mass value="0.0171001"/>
<inertia ixx="2.29537e-06" ixy="-5.64962e-13"  ixz="-2.154e-13" iyy="1.52616e-06" iyz="-6.36265e-08" izz="2.01963e-06" />
</inertial>
</link>
<joint name="body_1_body_1_3_motor_fixing" type="fixed">
<origin xyz="-0.0485 1.04083e-17 0.0143" rpy="-3.2499e-16 5.88139e-16 1.5708" />
<parent link="body_1" />
<child link="body_1_3_motor" />
<axis xyz="0 0 0"/>
</joint>

<link name="body_1_4_horn">
<visual>
<geometry>
<mesh filename="package://horn.stl"/>
</geometry>
<material name="body_1_4_horn_material">
<color rgba="0.917647 0.917647 0.917647 1.0"/>
</material>
</visual>
<collision>
<geometry>
<mesh filename="package://horn.stl"/>
</geometry>
<material name="body_1_4_horn_material">
<color rgba="0.917647 0.917647 0.917647 1.0"/>
</material>
</collision>
<inertial>
<origin xyz="-2.29324e-19 -1.05216e-18 -0.0134483" rpy="0 0 0"/>
<mass value="0.000575062"/>
<inertia ixx="1.30173e-08" ixy="0"  ixz="0" iyy="1.30173e-08" iyz="0" izz="2.51949e-08" />
</inertial>
</link>
<joint name="body_1_body_1_4_horn_fixing" type="fixed">
<origin xyz="0.0485 -1.94242e-17 0.0143" rpy="0 -0 1.45228" />
<parent link="body_1" />
<child link="body_1_4_horn" />
<axis xyz="0 0 0"/>
</joint>

<link name="body_1_5_horn">
<visual>
<geometry>
<mesh filename="package://horn.stl"/>
</geometry>
<material name="body_1_5_horn_material">
<color rgba="0.917647 0.917647 0.917647 1.0"/>
</material>
</visual>
<collision>
<geometry>
<mesh filename="package://horn.stl"/>
</geometry>
<material name="body_1_5_horn_material">
<color rgba="0.917647 0.917647 0.917647 1.0"/>
</material>
</collision>
<inertial>
<origin xyz="-2.29324e-19 -1.05216e-18 -0.0134483" rpy="0 0 0"/>
<mass value="0.000575062"/>
<inertia ixx="1.30173e-08" ixy="0"  ixz="0" iyy="1.30173e-08" iyz="0" izz="2.51949e-08" />
</inertial>
</link>
<joint name="body_1_body_1_5_horn_fixing" type="fixed">
<origin xyz="-0.0485 2.50633e-16 0.0143" rpy="0 -0 1.53832" />
<parent link="body_1" />
<child link="body_1_5_horn" />
<axis xyz="0 0 0"/>
</joint>

<link name="body_1_6_motor">
<visual>
<geometry>
<mesh filename="package://motor.stl"/>
</geometry>
<material name="body_1_6_motor_material">
<color rgba="0.470588 0.470588 0.470588 1.0"/>
</material>
</visual>
<collision>
<geometry>
<mesh filename="package://motor.stl"/>
</geometry>
<material name="body_1_6_motor_material">
<color rgba="0.470588 0.470588 0.470588 1.0"/>
</material>
</collision>
<inertial>
<origin xyz="2.21444e-09 -0.00683721 0.000497669" rpy="0 0 0"/>
<mass value="0.0171001"/>
<inertia ixx="2.29537e-06" ixy="-5.64962e-13"  ixz="-2.154e-13" iyy="1.52616e-06" iyz="-6.36265e-08" izz="2.01963e-06" />
</inertial>
</link>
<joint name="body_1_body_1_6_motor_fixing" type="fixed">
<origin xyz="3.64292e-17 0.0485 0.0143" rpy="1.92729e-20 -4.99868e-19 2.77556e-17" />
<parent link="body_1" />
<child link="body_1_6_motor" />
<axis xyz="0 0 0"/>
</joint>

<link name="body_1_7_body">
<visual>
<geometry>
<mesh filename="package://body.stl"/>
</geometry>
<material name="body_1_7_body_material">
<color rgba="0.972549 0.529412 0.00392157 1.0"/>
</material>
</visual>
<collision>
<geometry>
<mesh filename="package://body.stl"/>
</geometry>
<material name="body_1_7_body_material">
<color rgba="0.972549 0.529412 0.00392157 1.0"/>
</material>
</collision>
<inertial>
<origin xyz="1.71078e-19 5.13234e-19 0.00115" rpy="0 0 0"/>
<mass value="0.00508653"/>
<inertia ixx="8.92046e-07" ixy="0"  ixz="0" iyy="8.92046e-07" iyz="0" izz="1.77961e-06" />
</inertial>
</link>
<joint name="body_1_body_1_7_body_fixing" type="fixed">
<origin xyz="0 3.46945e-18 0.0286" rpy="3.14159 -0 0" />
<parent link="body_1" />
<child link="body_1_7_body" />
<axis xyz="0 0 0"/>
</joint>

<link name="body_1_8_motor">
<visual>
<geometry>
<mesh filename="package://motor.stl"/>
</geometry>
<material name="body_1_8_motor_material">
<color rgba="0.470588 0.470588 0.470588 1.0"/>
</material>
</visual>
<collision>
<geometry>
<mesh filename="package://motor.stl"/>
</geometry>
<material name="body_1_8_motor_material">
<color rgba="0.470588 0.470588 0.470588 1.0"/>
</material>
</collision>
<inertial>
<origin xyz="2.21444e-09 -0.00683721 0.000497669" rpy="0 0 0"/>
<mass value="0.0171001"/>
<inertia ixx="2.29537e-06" ixy="-5.64962e-13"  ixz="-2.154e-13" iyy="1.52616e-06" iyz="-6.36265e-08" izz="2.01963e-06" />
</inertial>
</link>
<joint name="body_1_body_1_8_motor_fixing" type="fixed">
<origin xyz="-2.42861e-17 -0.0485 0.0143" rpy="-2.87004e-24 7.54228e-16 -3.14159" />
<parent link="body_1" />
<child link="body_1_8_motor" />
<axis xyz="0 0 0"/>
</joint>

<link name="body_1_9_horn">
<visual>
<geometry>
<mesh filename="package://horn.stl"/>
</geometry>
<material name="body_1_9_horn_material">
<color rgba="0.917647 0.917647 0.917647 1.0"/>
</material>
</visual>
<collision>
<geometry>
<mesh filename="package://horn.stl"/>
</geometry>
<material name="body_1_9_horn_material">
<color rgba="0.917647 0.917647 0.917647 1.0"/>
</material>
</collision>
<inertial>
<origin xyz="-2.29324e-19 -1.05216e-18 -0.0134483" rpy="0 0 0"/>
<mass value="0.000575062"/>
<inertia ixx="1.30173e-08" ixy="0"  ixz="0" iyy="1.30173e-08" iyz="0" izz="2.51949e-08" />
</inertial>
</link>
<joint name="body_1_body_1_9_horn_fixing" type="fixed">
<origin xyz="-9.66308e-18 0.0485 0.0143" rpy="0 -0 1.49355" />
<parent link="body_1" />
<child link="body_1_9_horn" />
<axis xyz="0 0 0"/>
</joint>

<link name="doubleu_1">
<inertial>
<origin xyz="0 0 0" rpy="0 0 0" />
<mass value="1e-9" />
<inertia ixx="0" ixy="0" ixz="0" iyy="0" iyz="0" izz="0" />
</inertial>
</link>
<link name="doubleu_1_0_u">
<visual>
<geometry>
<mesh filename="package://u.stl"/>
</geometry>
<material name="doubleu_1_0_u_material">
<color rgba="0.972549 0.529412 0.00392157 1.0"/>
</material>
</visual>
<collision>
<geometry>
<mesh filename="package://u.stl"/>
</geometry>
<material name="doubleu_1_0_u_material">
<color rgba="0.972549 0.529412 0.00392157 1.0"/>
</material>
</collision>
<inertial>
<origin xyz="3.08295e-18 4.6092e-18 -0.00844242" rpy="0 0 0"/>
<mass value="0.00415349"/>
<inertia ixx="1.25185e-06" ixy="0"  ixz="0" iyy="5.73141e-07" iyz="0" izz="9.62751e-07" />
</inertial>
</link>
<joint name="doubleu_1_doubleu_1_0_u_fixing" type="fixed">
<origin xyz="-2.46519e-32 -0.015 0.018" rpy="0 -1.27283e-32 0" />
<parent link="doubleu_1" />
<child link="doubleu_1_0_u" />
<axis xyz="0 0 0"/>
</joint>

<link name="doubleu_1_1_u">
<visual>
<geometry>
<mesh filename="package://u.stl"/>
</geometry>
<material name="doubleu_1_1_u_material">
<color rgba="0.972549 0.529412 0.00392157 1.0"/>
</material>
</visual>
<collision>
<geometry>
<mesh filename="package://u.stl"/>
</geometry>
<material name="doubleu_1_1_u_material">
<color rgba="0.972549 0.529412 0.00392157 1.0"/>
</material>
</collision>
<inertial>
<origin xyz="3.08295e-18 4.6092e-18 -0.00844242" rpy="0 0 0"/>
<mass value="0.00415349"/>
<inertia ixx="1.25185e-06" ixy="0"  ixz="0" iyy="5.73141e-07" iyz="0" izz="9.62751e-07" />
</inertial>
</link>
<joint name="doubleu_1_doubleu_1_1_u_fixing" type="fixed">
<origin xyz="2.015e-16 -0.015 0.0226" rpy="3.14159 -2.97579e-17 1.5708" />
<parent link="doubleu_1" />
<child link="doubleu_1_1_u" />
<axis xyz="0 0 0"/>
</joint>

<link name="platesblock_1">
<inertial>
<origin xyz="0 0 0" rpy="0 0 0" />
<mass value="1e-9" />
<inertia ixx="0" ixy="0" ixz="0" iyy="0" iyz="0" izz="0" />
</inertial>
</link>
<link name="platesblock_1_0_horn">
<visual>
<geometry>
<mesh filename="package://horn.stl"/>
</geometry>
<material name="platesblock_1_0_horn_material">
<color rgba="0.917647 0.917647 0.917647 1.0"/>
</material>
</visual>
<collision>
<geometry>
<mesh filename="package://horn.stl"/>
</geometry>
<material name="platesblock_1_0_horn_material">
<color rgba="0.917647 0.917647 0.917647 1.0"/>
</material>
</collision>
<inertial>
<origin xyz="-2.29324e-19 -1.05216e-18 -0.0134483" rpy="0 0 0"/>
<mass value="0.000575062"/>
<inertia ixx="1.30173e-08" ixy="0"  ixz="0" iyy="1.30173e-08" iyz="0" izz="2.51949e-08" />
</inertial>
</link>
<joint name="platesblock_1_platesblock_1_0_horn_fixing" type="fixed">
<origin xyz="4.38421e-10 -0.063 0.015" rpy="-9.38471e-16 4.96057e-15 2.3057" />
<parent link="platesblock_1" />
<child link="platesblock_1_0_horn" />
<axis xyz="0 0 0"/>
</joint>

<link name="platesblock_1_1_horn">
<visual>
<geometry>
<mesh filename="package://horn.stl"/>
</geometry>
<material name="platesblock_1_1_horn_material">
<color rgba="0.917647 0.917647 0.917647 1.0"/>
</material>
</visual>
<collision>
<geometry>
<mesh filename="package://horn.stl"/>
</geometry>
<material name="platesblock_1_1_horn_material">
<color rgba="0.917647 0.917647 0.917647 1.0"/>
</material>
</collision>
<inertial>
<origin xyz="-2.29324e-19 -1.05216e-18 -0.0134483" rpy="0 0 0"/>
<mass value="0.000575062"/>
<inertia ixx="1.30173e-08" ixy="0"  ixz="0" iyy="1.30173e-08" iyz="0" izz="2.51949e-08" />
</inertial>
</link>
<joint name="platesblock_1_platesblock_1_1_horn_fixing" type="fixed">
<origin xyz="0 0 0.015" rpy="1.30229e-31 4.11092e-32 -2.18285e-25" />
<parent link="platesblock_1" />
<child link="platesblock_1_1_horn" />
<axis xyz="0 0 0"/>
</joint>

<link name="platesblock_1_2_motor">
<visual>
<geometry>
<mesh filename="package://motor.stl"/>
</geometry>
<material name="platesblock_1_2_motor_material">
<color rgba="0.470588 0.470588 0.470588 1.0"/>
</material>
</visual>
<collision>
<geometry>
<mesh filename="package://motor.stl"/>
</geometry>
<material name="platesblock_1_2_motor_material">
<color rgba="0.470588 0.470588 0.470588 1.0"/>
</material>
</collision>
<inertial>
<origin xyz="2.21444e-09 -0.00683721 0.000497669" rpy="0 0 0"/>
<mass value="0.0171001"/>
<inertia ixx="2.29537e-06" ixy="-5.64962e-13"  ixz="-2.154e-13" iyy="1.52616e-06" iyz="-6.36265e-08" izz="2.01963e-06" />
</inertial>
</link>
<joint name="platesblock_1_platesblock_1_2_motor_fixing" type="fixed">
<origin xyz="4.38421e-10 -0.063 0.015" rpy="1.07562e-15 2.57573e-17 -3.14159" />
<parent link="platesblock_1" />
<child link="platesblock_1_2_motor" />
<axis xyz="0 0 0"/>
</joint>

<link name="platesblock_1_3_motor">
<visual>
<geometry>
<mesh filename="package://motor.stl"/>
</geometry>
<material name="platesblock_1_3_motor_material">
<color rgba="0.470588 0.470588 0.470588 1.0"/>
</material>
</visual>
<collision>
<geometry>
<mesh filename="package://motor.stl"/>
</geometry>
<material name="platesblock_1_3_motor_material">
<color rgba="0.470588 0.470588 0.470588 1.0"/>
</material>
</collision>
<inertial>
<origin xyz="2.21444e-09 -0.00683721 0.000497669" rpy="0 0 0"/>
<mass value="0.0171001"/>
<inertia ixx="2.29537e-06" ixy="-5.64962e-13"  ixz="-2.154e-13" iyy="1.52616e-06" iyz="-6.36265e-08" izz="2.01963e-06" />
</inertial>
</link>
<joint name="platesblock_1_platesblock_1_3_motor_fixing" type="fixed">
<origin xyz="1.04083e-17 1.38778e-17 0.015" rpy="-9.36845e-16 -2.57573e-17 6.95905e-09" />
<parent link="platesblock_1" />
<child link="platesblock_1_3_motor" />
<axis xyz="0 0 0"/>
</joint>

<link name="platesblock_1_4_plate">
<visual>
<geometry>
<mesh filename="package://plate.stl"/>
</geometry>
<material name="platesblock_1_4_plate_material">
<color rgba="0.972549 0.529412 0.00392157 1.0"/>
</material>
</visual>
<collision>
<geometry>
<mesh filename="package://plate.stl"/>
</geometry>
<material name="platesblock_1_4_plate_material">
<color rgba="0.972549 0.529412 0.00392157 1.0"/>
</material>
</collision>
<inertial>
<origin xyz="0.0375 -1.298e-18 0.00115" rpy="0 0 0"/>
<mass value="0.00321261"/>
<inertia ixx="1.09131e-07" ixy="0"  ixz="0" iyy="1.41928e-06" iyz="0" izz="1.52558e-06" />
</inertial>
</link>
<joint name="platesblock_1_platesblock_1_4_plate_fixing" type="fixed">
<origin xyz="0.0143 0.006 0.015" rpy="1.5708 -9.76763e-16 -1.5708" />
<parent link="platesblock_1" />
<child link="platesblock_1_4_plate" />
<axis xyz="0 0 0"/>
</joint>

<link name="platesblock_1_5_plate">
<visual>
<geometry>
<mesh filename="package://plate.stl"/>
</geometry>
<material name="platesblock_1_5_plate_material">
<color rgba="0.972549 0.529412 0.00392157 1.0"/>
</material>
</visual>
<collision>
<geometry>
<mesh filename="package://plate.stl"/>
</geometry>
<material name="platesblock_1_5_plate_material">
<color rgba="0.972549 0.529412 0.00392157 1.0"/>
</material>
</collision>
<inertial>
<origin xyz="0.0375 -1.298e-18 0.00115" rpy="0 0 0"/>
<mass value="0.00321261"/>
<inertia ixx="1.09131e-07" ixy="0"  ixz="0" iyy="1.41928e-06" iyz="0" izz="1.52558e-06" />
</inertial>
</link>
<joint name="platesblock_1_platesblock_1_5_plate_fixing" type="fixed">
<origin xyz="-0.012 0.006 0.015" rpy="1.5708 -1.42317e-15 -1.5708" />
<parent link="platesblock_1" />
<child link="platesblock_1_5_plate" />
<axis xyz="0 0 0"/>
</joint>

<link name="hornside_1">
<inertial>
<origin xyz="0 0 0" rpy="0 0 0" />
<mass value="1e-9" />
<inertia ixx="0" ixy="0" ixz="0" iyy="0" iyz="0" izz="0" />
</inertial>
</link>
<link name="hornside_1_0_horn">
<visual>
<geometry>
<mesh filename="package://horn.stl"/>
</geometry>
<material name="hornside_1_0_horn_material">
<color rgba="0.917647 0.917647 0.917647 1.0"/>
</material>
</visual>
<collision>
<geometry>
<mesh filename="package://horn.stl"/>
</geometry>
<material name="hornside_1_0_horn_material">
<color rgba="0.917647 0.917647 0.917647 1.0"/>
</material>
</collision>
<inertial>
<origin xyz="-2.29324e-19 -1.05216e-18 -0.0134483" rpy="0 0 0"/>
<mass value="0.000575062"/>
<inertia ixx="1.30173e-08" ixy="0"  ixz="0" iyy="1.30173e-08" iyz="0" izz="2.51949e-08" />
</inertial>
</link>
<joint name="hornside_1_hornside_1_0_horn_fixing" type="fixed">
<origin xyz="1.92554e-16 0.071 -0.015" rpy="-3.14159 2.14868e-15 -1.72183" />
<parent link="hornside_1" />
<child link="hornside_1_0_horn" />
<axis xyz="0 0 0"/>
</joint>

<link name="hornside_1_1_motor">
<visual>
<geometry>
<mesh filename="package://motor.stl"/>
</geometry>
<material name="hornside_1_1_motor_material">
<color rgba="0.470588 0.470588 0.470588 1.0"/>
</material>
</visual>
<collision>
<geometry>
<mesh filename="package://motor.stl"/>
</geometry>
<material name="hornside_1_1_motor_material">
<color rgba="0.470588 0.470588 0.470588 1.0"/>
</material>
</collision>
<inertial>
<origin xyz="2.21444e-09 -0.00683721 0.000497669" rpy="0 0 0"/>
<mass value="0.0171001"/>
<inertia ixx="2.29537e-06" ixy="-5.64962e-13"  ixz="-2.154e-13" iyy="1.52616e-06" iyz="-6.36265e-08" izz="2.01963e-06" />
</inertial>
</link>
<joint name="hornside_1_hornside_1_1_motor_fixing" type="fixed">
<origin xyz="1.99493e-16 0.071 -0.015" rpy="3.14159 -2.67062e-31 3.14159" />
<parent link="hornside_1" />
<child link="hornside_1_1_motor" />
<axis xyz="0 0 0"/>
</joint>

<link name="hornside_1_2_horntobottom">
<visual>
<geometry>
<mesh filename="package://horntobottom.stl"/>
</geometry>
<material name="hornside_1_2_horntobottom_material">
<color rgba="0.972549 0.529412 0.00392157 1.0"/>
</material>
</visual>
<collision>
<geometry>
<mesh filename="package://horntobottom.stl"/>
</geometry>
<material name="hornside_1_2_horntobottom_material">
<color rgba="0.972549 0.529412 0.00392157 1.0"/>
</material>
</collision>
<inertial>
<origin xyz="-4.74942e-15 0.0245577 0.0157805" rpy="0 0 0"/>
<mass value="0.00214736"/>
<inertia ixx="6.93961e-07" ixy="0"  ixz="0" iyy="8.42583e-08" iyz="1.70989e-08" izz="7.72522e-07" />
</inertial>
</link>
<joint name="hornside_1_hornside_1_2_horntobottom_fixing" type="fixed">
<origin xyz="-7.28584e-17 2.22045e-16 -0.015" rpy="3.14159 5.08696e-16 3.14159" />
<parent link="hornside_1" />
<child link="hornside_1_2_horntobottom" />
<axis xyz="0 0 0"/>
</joint>

<link name="hornside_1_3_horntobottom">
<visual>
<geometry>
<mesh filename="package://horntobottom.stl"/>
</geometry>
<material name="hornside_1_3_horntobottom_material">
<color rgba="0.972549 0.529412 0.00392157 1.0"/>
</material>
</visual>
<collision>
<geometry>
<mesh filename="package://horntobottom.stl"/>
</geometry>
<material name="hornside_1_3_horntobottom_material">
<color rgba="0.972549 0.529412 0.00392157 1.0"/>
</material>
</collision>
<inertial>
<origin xyz="-4.74942e-15 0.0245577 0.0157805" rpy="0 0 0"/>
<mass value="0.00214736"/>
<inertia ixx="6.93961e-07" ixy="0"  ixz="0" iyy="8.42583e-08" iyz="1.70989e-08" izz="7.72522e-07" />
</inertial>
</link>
<joint name="hornside_1_hornside_1_3_horntobottom_fixing" type="fixed">
<origin xyz="-1.73472e-18 0 -0.015" rpy="1.21892e-31 6.14016e-32 -3.28029e-33" />
<parent link="hornside_1" />
<child link="hornside_1_3_horntobottom" />
<axis xyz="0 0 0"/>
</joint>

<link name="leg_1">
<inertial>
<origin xyz="0 0 0" rpy="0 0 0" />
<mass value="1e-9" />
<inertia ixx="0" ixy="0" ixz="0" iyy="0" iyz="0" izz="0" />
</inertial>
</link>
<link name="leg_1_0_leg">
<visual>
<geometry>
<mesh filename="package://leg.stl"/>
</geometry>
<material name="leg_1_0_leg_material">
<color rgba="0.972549 0.529412 0.00392157 1.0"/>
</material>
</visual>
<collision>
<geometry>
<mesh filename="package://leg.stl"/>
</geometry>
<material name="leg_1_0_leg_material">
<color rgba="0.972549 0.529412 0.00392157 1.0"/>
</material>
</collision>
<inertial>
<origin xyz="-2.58551e-17 -1.31238e-17 -0.0546998" rpy="0 0 0"/>
<mass value="0.0151258"/>
<inertia ixx="1.99013e-05" ixy="0"  ixz="0" iyy="1.74063e-05" iyz="0" izz="3.49853e-06" />
</inertial>
</link>
<joint name="leg_1_leg_1_0_leg_fixing" type="fixed">
<origin xyz="0 0.015 0" rpy="6.26698e-31 -3.69779e-32 -2.31112e-32" />
<parent link="leg_1" />
<child link="leg_1_0_leg" />
<axis xyz="0 0 0"/>
</joint>

<joint name="leg1_d" type="revolute">
<origin xyz="2.30718e-16 0.071 1.89085e-16" rpy="-1.5708 1.58567e-16 -3.14159" />
<parent link="hornside_1" />
<child link="leg_1" />
<axis xyz="0 1 0"/>
<limit effort="1.5" velocity="22" />
<joint_properties friction="0.0"/>
</joint>

<joint name="leg1_c" type="revolute">
<origin xyz="4.38421e-10 -0.063 3.67761e-16" rpy="3.14159 -1.2803e-15 6.95905e-09" />
<parent link="platesblock_1" />
<child link="hornside_1" />
<axis xyz="0 0 -1"/>
<limit effort="1.5" velocity="22" />
<joint_properties friction="0.0"/>
</joint>

<joint name="leg1_b" type="revolute">
<origin xyz="0.015 -0.015 0.0406" rpy="-1.5708 -6.95905e-09 1.5708" />
<parent link="doubleu_1" />
<child link="platesblock_1" />
<axis xyz="0 0 1"/>
<limit effort="1.5" velocity="22" />
<joint_properties friction="0.0"/>
</joint>

<joint name="leg1_a" type="revolute">
<origin xyz="-0.0485 6.25371e-18 -0.0007" rpy="-1.5708 1.60727e-17 1.5708" />
<parent link="body_1" />
<child link="doubleu_1" />
<axis xyz="0 -1 0"/>
<limit effort="1.5" velocity="22" />
<joint_properties friction="0.0"/>
</joint>

<link name="doubleu_2">
<inertial>
<origin xyz="0 0 0" rpy="0 0 0" />
<mass value="1e-9" />
<inertia ixx="0" ixy="0" ixz="0" iyy="0" iyz="0" izz="0" />
</inertial>
</link>
<link name="doubleu_2_0_u">
<visual>
<geometry>
<mesh filename="package://u.stl"/>
</geometry>
<material name="doubleu_2_0_u_material">
<color rgba="0.972549 0.529412 0.00392157 1.0"/>
</material>
</visual>
<collision>
<geometry>
<mesh filename="package://u.stl"/>
</geometry>
<material name="doubleu_2_0_u_material">
<color rgba="0.972549 0.529412 0.00392157 1.0"/>
</material>
</collision>
<inertial>
<origin xyz="3.08295e-18 4.6092e-18 -0.00844242" rpy="0 0 0"/>
<mass value="0.00415349"/>
<inertia ixx="1.25185e-06" ixy="0"  ixz="0" iyy="5.73141e-07" iyz="0" izz="9.62751e-07" />
</inertial>
</link>
<joint name="doubleu_2_doubleu_2_0_u_fixing" type="fixed">
<origin xyz="0 -0.015 0.018" rpy="1.18235e-45 1.15043e-32 2.34174e-32" />
<parent link="doubleu_2" />
<child link="doubleu_2_0_u" />
<axis xyz="0 0 0"/>
</joint>

<link name="doubleu_2_1_u">
<visual>
<geometry>
<mesh filename="package://u.stl"/>
</geometry>
<material name="doubleu_2_1_u_material">
<color rgba="0.972549 0.529412 0.00392157 1.0"/>
</material>
</visual>
<collision>
<geometry>
<mesh filename="package://u.stl"/>
</geometry>
<material name="doubleu_2_1_u_material">
<color rgba="0.972549 0.529412 0.00392157 1.0"/>
</material>
</collision>
<inertial>
<origin xyz="3.08295e-18 4.6092e-18 -0.00844242" rpy="0 0 0"/>
<mass value="0.00415349"/>
<inertia ixx="1.25185e-06" ixy="0"  ixz="0" iyy="5.73141e-07" iyz="0" izz="9.62751e-07" />
</inertial>
</link>
<joint name="doubleu_2_doubleu_2_1_u_fixing" type="fixed">
<origin xyz="2.97268e-16 -0.015 0.0226" rpy="3.14159 -2.49859e-16 1.5708" />
<parent link="doubleu_2" />
<child link="doubleu_2_1_u" />
<axis xyz="0 0 0"/>
</joint>

<link name="platesblock_2">
<inertial>
<origin xyz="0 0 0" rpy="0 0 0" />
<mass value="1e-9" />
<inertia ixx="0" ixy="0" ixz="0" iyy="0" iyz="0" izz="0" />
</inertial>
</link>
<link name="platesblock_2_0_plate">
<visual>
<geometry>
<mesh filename="package://plate.stl"/>
</geometry>
<material name="platesblock_2_0_plate_material">
<color rgba="0.972549 0.529412 0.00392157 1.0"/>
</material>
</visual>
<collision>
<geometry>
<mesh filename="package://plate.stl"/>
</geometry>
<material name="platesblock_2_0_plate_material">
<color rgba="0.972549 0.529412 0.00392157 1.0"/>
</material>
</collision>
<inertial>
<origin xyz="0.0375 -1.298e-18 0.00115" rpy="0 0 0"/>
<mass value="0.00321261"/>
<inertia ixx="1.09131e-07" ixy="0"  ixz="0" iyy="1.41928e-06" iyz="0" izz="1.52558e-06" />
</inertial>
</link>
<joint name="platesblock_2_platesblock_2_0_plate_fixing" type="fixed">
<origin xyz="0.006 0.012 0.015" rpy="1.5708 -1.66196e-14 3.14159" />
<parent link="platesblock_2" />
<child link="platesblock_2_0_plate" />
<axis xyz="0 0 0"/>
</joint>

<link name="platesblock_2_1_plate">
<visual>
<geometry>
<mesh filename="package://plate.stl"/>
</geometry>
<material name="platesblock_2_1_plate_material">
<color rgba="0.972549 0.529412 0.00392157 1.0"/>
</material>
</visual>
<collision>
<geometry>
<mesh filename="package://plate.stl"/>
</geometry>
<material name="platesblock_2_1_plate_material">
<color rgba="0.972549 0.529412 0.00392157 1.0"/>
</material>
</collision>
<inertial>
<origin xyz="0.0375 -1.298e-18 0.00115" rpy="0 0 0"/>
<mass value="0.00321261"/>
<inertia ixx="1.09131e-07" ixy="0"  ixz="0" iyy="1.41928e-06" iyz="0" izz="1.52558e-06" />
</inertial>
</link>
<joint name="platesblock_2_platesblock_2_1_plate_fixing" type="fixed">
<origin xyz="0.006 -0.0143 0.015" rpy="1.5708 -2.3e-16 -3.14159" />
<parent link="platesblock_2" />
<child link="platesblock_2_1_plate" />
<axis xyz="0 0 0"/>
</joint>

<link name="platesblock_2_2_horn">
<visual>
<geometry>
<mesh filename="package://horn.stl"/>
</geometry>
<material name="platesblock_2_2_horn_material">
<color rgba="0.917647 0.917647 0.917647 1.0"/>
</material>
</visual>
<collision>
<geometry>
<mesh filename="package://horn.stl"/>
</geometry>
<material name="platesblock_2_2_horn_material">
<color rgba="0.917647 0.917647 0.917647 1.0"/>
</material>
</collision>
<inertial>
<origin xyz="-2.29324e-19 -1.05216e-18 -0.0134483" rpy="0 0 0"/>
<mass value="0.000575062"/>
<inertia ixx="1.30173e-08" ixy="0"  ixz="0" iyy="1.30173e-08" iyz="0" izz="2.51949e-08" />
</inertial>
</link>
<joint name="platesblock_2_platesblock_2_2_horn_fixing" type="fixed">
<origin xyz="-0.063 -1.38604e-15 0.015" rpy="1.27451e-15 5.79534e-16 1.0396" />
<parent link="platesblock_2" />
<child link="platesblock_2_2_horn" />
<axis xyz="0 0 0"/>
</joint>

<link name="platesblock_2_3_horn">
<visual>
<geometry>
<mesh filename="package://horn.stl"/>
</geometry>
<material name="platesblock_2_3_horn_material">
<color rgba="0.917647 0.917647 0.917647 1.0"/>
</material>
</visual>
<collision>
<geometry>
<mesh filename="package://horn.stl"/>
</geometry>
<material name="platesblock_2_3_horn_material">
<color rgba="0.917647 0.917647 0.917647 1.0"/>
</material>
</collision>
<inertial>
<origin xyz="-2.29324e-19 -1.05216e-18 -0.0134483" rpy="0 0 0"/>
<mass value="0.000575062"/>
<inertia ixx="1.30173e-08" ixy="0"  ixz="0" iyy="1.30173e-08" iyz="0" izz="2.51949e-08" />
</inertial>
</link>
<joint name="platesblock_2_platesblock_2_3_horn_fixing" type="fixed">
<origin xyz="0 0 0.015" rpy="3.72299e-32 7.16852e-31 1.7547e-32" />
<parent link="platesblock_2" />
<child link="platesblock_2_3_horn" />
<axis xyz="0 0 0"/>
</joint>

<link name="platesblock_2_4_motor">
<visual>
<geometry>
<mesh filename="package://motor.stl"/>
</geometry>
<material name="platesblock_2_4_motor_material">
<color rgba="0.470588 0.470588 0.470588 1.0"/>
</material>
</visual>
<collision>
<geometry>
<mesh filename="package://motor.stl"/>
</geometry>
<material name="platesblock_2_4_motor_material">
<color rgba="0.470588 0.470588 0.470588 1.0"/>
</material>
</collision>
<inertial>
<origin xyz="2.21444e-09 -0.00683721 0.000497669" rpy="0 0 0"/>
<mass value="0.0171001"/>
<inertia ixx="2.29537e-06" ixy="-5.64962e-13"  ixz="-2.154e-13" iyy="1.52616e-06" iyz="-6.36265e-08" izz="2.01963e-06" />
</inertial>
</link>
<joint name="platesblock_2_platesblock_2_4_motor_fixing" type="fixed">
<origin xyz="-0.063 -1.39645e-15 0.015" rpy="1.54634e-15 -1.7074e-18 1.5708" />
<parent link="platesblock_2" />
<child link="platesblock_2_4_motor" />
<axis xyz="0 0 0"/>
</joint>

<link name="platesblock_2_5_motor">
<visual>
<geometry>
<mesh filename="package://motor.stl"/>
</geometry>
<material name="platesblock_2_5_motor_material">
<color rgba="0.470588 0.470588 0.470588 1.0"/>
</material>
</visual>
<collision>
<geometry>
<mesh filename="package://motor.stl"/>
</geometry>
<material name="platesblock_2_5_motor_material">
<color rgba="0.470588 0.470588 0.470588 1.0"/>
</material>
</collision>
<inertial>
<origin xyz="2.21444e-09 -0.00683721 0.000497669" rpy="0 0 0"/>
<mass value="0.0171001"/>
<inertia ixx="2.29537e-06" ixy="-5.64962e-13"  ixz="-2.154e-13" iyy="1.52616e-06" iyz="-6.36265e-08" izz="2.01963e-06" />
</inertial>
</link>
<joint name="platesblock_2_platesblock_2_5_motor_fixing" type="fixed">
<origin xyz="-1.38778e-17 -6.93889e-18 0.015" rpy="-2.59685e-17 1.7074e-18 -1.5708" />
<parent link="platesblock_2" />
<child link="platesblock_2_5_motor" />
<axis xyz="0 0 0"/>
</joint>

<link name="hornside_2">
<inertial>
<origin xyz="0 0 0" rpy="0 0 0" />
<mass value="1e-9" />
<inertia ixx="0" ixy="0" ixz="0" iyy="0" iyz="0" izz="0" />
</inertial>
</link>
<link name="hornside_2_0_horntobottom">
<visual>
<geometry>
<mesh filename="package://horntobottom.stl"/>
</geometry>
<material name="hornside_2_0_horntobottom_material">
<color rgba="0.972549 0.529412 0.00392157 1.0"/>
</material>
</visual>
<collision>
<geometry>
<mesh filename="package://horntobottom.stl"/>
</geometry>
<material name="hornside_2_0_horntobottom_material">
<color rgba="0.972549 0.529412 0.00392157 1.0"/>
</material>
</collision>
<inertial>
<origin xyz="-4.74942e-15 0.0245577 0.0157805" rpy="0 0 0"/>
<mass value="0.00214736"/>
<inertia ixx="6.93961e-07" ixy="0"  ixz="0" iyy="8.42583e-08" iyz="1.70989e-08" izz="7.72522e-07" />
</inertial>
</link>
<joint name="hornside_2_hornside_2_0_horntobottom_fixing" type="fixed">
<origin xyz="1.73472e-18 0 -0.015" rpy="-1.16622e-31 8.54906e-33 1.02928e-45" />
<parent link="hornside_2" />
<child link="hornside_2_0_horntobottom" />
<axis xyz="0 0 0"/>
</joint>

<link name="hornside_2_1_horntobottom">
<visual>
<geometry>
<mesh filename="package://horntobottom.stl"/>
</geometry>
<material name="hornside_2_1_horntobottom_material">
<color rgba="0.972549 0.529412 0.00392157 1.0"/>
</material>
</visual>
<collision>
<geometry>
<mesh filename="package://horntobottom.stl"/>
</geometry>
<material name="hornside_2_1_horntobottom_material">
<color rgba="0.972549 0.529412 0.00392157 1.0"/>
</material>
</collision>
<inertial>
<origin xyz="-4.74942e-15 0.0245577 0.0157805" rpy="0 0 0"/>
<mass value="0.00214736"/>
<inertia ixx="6.93961e-07" ixy="0"  ixz="0" iyy="8.42583e-08" iyz="1.70989e-08" izz="7.72522e-07" />
</inertial>
</link>
<joint name="hornside_2_hornside_2_1_horntobottom_fixing" type="fixed">
<origin xyz="5.72459e-17 2.22045e-16 -0.015" rpy="-3.14159 -1.39827e-15 -3.14159" />
<parent link="hornside_2" />
<child link="hornside_2_1_horntobottom" />
<axis xyz="0 0 0"/>
</joint>

<link name="hornside_2_2_motor">
<visual>
<geometry>
<mesh filename="package://motor.stl"/>
</geometry>
<material name="hornside_2_2_motor_material">
<color rgba="0.470588 0.470588 0.470588 1.0"/>
</material>
</visual>
<collision>
<geometry>
<mesh filename="package://motor.stl"/>
</geometry>
<material name="hornside_2_2_motor_material">
<color rgba="0.470588 0.470588 0.470588 1.0"/>
</material>
</collision>
<inertial>
<origin xyz="2.21444e-09 -0.00683721 0.000497669" rpy="0 0 0"/>
<mass value="0.0171001"/>
<inertia ixx="2.29537e-06" ixy="-5.64962e-13"  ixz="-2.154e-13" iyy="1.52616e-06" iyz="-6.36265e-08" izz="2.01963e-06" />
</inertial>
</link>
<joint name="hornside_2_hornside_2_2_motor_fixing" type="fixed">
<origin xyz="5.89806e-17 0.071 -0.015" rpy="-3.14159 -2.25342e-15 -3.14159" />
<parent link="hornside_2" />
<child link="hornside_2_2_motor" />
<axis xyz="0 0 0"/>
</joint>

<link name="hornside_2_3_horn">
<visual>
<geometry>
<mesh filename="package://horn.stl"/>
</geometry>
<material name="hornside_2_3_horn_material">
<color rgba="0.917647 0.917647 0.917647 1.0"/>
</material>
</visual>
<collision>
<geometry>
<mesh filename="package://horn.stl"/>
</geometry>
<material name="hornside_2_3_horn_material">
<color rgba="0.917647 0.917647 0.917647 1.0"/>
</material>
</collision>
<inertial>
<origin xyz="-2.29324e-19 -1.05216e-18 -0.0134483" rpy="0 0 0"/>
<mass value="0.000575062"/>
<inertia ixx="1.30173e-08" ixy="0"  ixz="0" iyy="1.30173e-08" iyz="0" izz="2.51949e-08" />
</inertial>
</link>
<joint name="hornside_2_hornside_2_3_horn_fixing" type="fixed">
<origin xyz="6.07153e-17 0.071 -0.015" rpy="3.14159 1.95505e-15 0.108926" />
<parent link="hornside_2" />
<child link="hornside_2_3_horn" />
<axis xyz="0 0 0"/>
</joint>

<link name="leg_2">
<inertial>
<origin xyz="0 0 0" rpy="0 0 0" />
<mass value="1e-9" />
<inertia ixx="0" ixy="0" ixz="0" iyy="0" iyz="0" izz="0" />
</inertial>
</link>
<link name="leg_2_0_leg">
<visual>
<geometry>
<mesh filename="package://leg.stl"/>
</geometry>
<material name="leg_2_0_leg_material">
<color rgba="0.972549 0.529412 0.00392157 1.0"/>
</material>
</visual>
<collision>
<geometry>
<mesh filename="package://leg.stl"/>
</geometry>
<material name="leg_2_0_leg_material">
<color rgba="0.972549 0.529412 0.00392157 1.0"/>
</material>
</collision>
<inertial>
<origin xyz="-2.58551e-17 -1.31238e-17 -0.0546998" rpy="0 0 0"/>
<mass value="0.0151258"/>
<inertia ixx="1.99013e-05" ixy="0"  ixz="0" iyy="1.74063e-05" iyz="0" izz="3.49853e-06" />
</inertial>
</link>
<joint name="leg_2_leg_2_0_leg_fixing" type="fixed">
<origin xyz="-1.73472e-18 0.015 0" rpy="-2.082e-30 -2.46519e-32 1.14045e-31" />
<parent link="leg_2" />
<child link="leg_2_0_leg" />
<axis xyz="0 0 0"/>
</joint>

<joint name="leg2_d" type="revolute">
<origin xyz="6.07153e-17 0.071 -7.28584e-16" rpy="-1.5708 -2.28533e-15 -3.14159" />
<parent link="hornside_2" />
<child link="leg_2" />
<axis xyz="0 1 0"/>
<limit effort="1.5" velocity="22" />
<joint_properties friction="0.0"/>
</joint>

<joint name="leg2_c" type="revolute">
<origin xyz="-0.063 -1.38604e-15 -9.36751e-17" rpy="-3.14159 1.0291e-15 -1.5708" />
<parent link="platesblock_2" />
<child link="hornside_2" />
<axis xyz="0 0 -1"/>
<limit effort="1.5" velocity="22" />
<joint_properties friction="0.0"/>
</joint>

<joint name="leg2_b" type="revolute">
<origin xyz="0.015 -0.015 0.0406" rpy="3.14159 1.5708 0" />
<parent link="doubleu_2" />
<child link="platesblock_2" />
<axis xyz="0 0 1"/>
<limit effort="1.5" velocity="22" />
<joint_properties friction="0.0"/>
</joint>

<joint name="leg2_a" type="revolute">
<origin xyz="-1.29821e-17 -0.0485 -0.0007" rpy="-1.5708 -4.14944e-16 -3.14159" />
<parent link="body_1" />
<child link="doubleu_2" />
<axis xyz="0 1 0"/>
<limit effort="1.5" velocity="22" />
<joint_properties friction="0.0"/>
</joint>

<link name="doubleu_3">
<inertial>
<origin xyz="0 0 0" rpy="0 0 0" />
<mass value="1e-9" />
<inertia ixx="0" ixy="0" ixz="0" iyy="0" iyz="0" izz="0" />
</inertial>
</link>
<link name="doubleu_3_0_u">
<visual>
<geometry>
<mesh filename="package://u.stl"/>
</geometry>
<material name="doubleu_3_0_u_material">
<color rgba="0.972549 0.529412 0.00392157 1.0"/>
</material>
</visual>
<collision>
<geometry>
<mesh filename="package://u.stl"/>
</geometry>
<material name="doubleu_3_0_u_material">
<color rgba="0.972549 0.529412 0.00392157 1.0"/>
</material>
</collision>
<inertial>
<origin xyz="3.08295e-18 4.6092e-18 -0.00844242" rpy="0 0 0"/>
<mass value="0.00415349"/>
<inertia ixx="1.25185e-06" ixy="0"  ixz="0" iyy="5.73141e-07" iyz="0" izz="9.62751e-07" />
</inertial>
</link>
<joint name="doubleu_3_doubleu_3_0_u_fixing" type="fixed">
<origin xyz="2.4436e-17 0.015 0.0226" rpy="-3.14159 8.35796e-23 1.5708" />
<parent link="doubleu_3" />
<child link="doubleu_3_0_u" />
<axis xyz="0 0 0"/>
</joint>

<link name="doubleu_3_1_u">
<visual>
<geometry>
<mesh filename="package://u.stl"/>
</geometry>
<material name="doubleu_3_1_u_material">
<color rgba="0.972549 0.529412 0.00392157 1.0"/>
</material>
</visual>
<collision>
<geometry>
<mesh filename="package://u.stl"/>
</geometry>
<material name="doubleu_3_1_u_material">
<color rgba="0.972549 0.529412 0.00392157 1.0"/>
</material>
</collision>
<inertial>
<origin xyz="3.08295e-18 4.6092e-18 -0.00844242" rpy="0 0 0"/>
<mass value="0.00415349"/>
<inertia ixx="1.25185e-06" ixy="0"  ixz="0" iyy="5.73141e-07" iyz="0" izz="9.62751e-07" />
</inertial>
</link>
<joint name="doubleu_3_doubleu_3_1_u_fixing" type="fixed">
<origin xyz="-9.24446e-33 0.015 0.018" rpy="3.35179e-39 -2.46519e-32 9.98425e-43" />
<parent link="doubleu_3" />
<child link="doubleu_3_1_u" />
<axis xyz="0 0 0"/>
</joint>

<link name="platesblock_3">
<inertial>
<origin xyz="0 0 0" rpy="0 0 0" />
<mass value="1e-9" />
<inertia ixx="0" ixy="0" ixz="0" iyy="0" iyz="0" izz="0" />
</inertial>
</link>
<link name="platesblock_3_0_plate">
<visual>
<geometry>
<mesh filename="package://plate.stl"/>
</geometry>
<material name="platesblock_3_0_plate_material">
<color rgba="0.972549 0.529412 0.00392157 1.0"/>
</material>
</visual>
<collision>
<geometry>
<mesh filename="package://plate.stl"/>
</geometry>
<material name="platesblock_3_0_plate_material">
<color rgba="0.972549 0.529412 0.00392157 1.0"/>
</material>
</collision>
<inertial>
<origin xyz="0.0375 -1.298e-18 0.00115" rpy="0 0 0"/>
<mass value="0.00321261"/>
<inertia ixx="1.09131e-07" ixy="0"  ixz="0" iyy="1.41928e-06" iyz="0" izz="1.52558e-06" />
</inertial>
</link>
<joint name="platesblock_3_platesblock_3_0_plate_fixing" type="fixed">
<origin xyz="0.006 0.012 0.015" rpy="1.5708 4.07293e-15 3.14159" />
<parent link="platesblock_3" />
<child link="platesblock_3_0_plate" />
<axis xyz="0 0 0"/>
</joint>

<link name="platesblock_3_1_motor">
<visual>
<geometry>
<mesh filename="package://motor.stl"/>
</geometry>
<material name="platesblock_3_1_motor_material">
<color rgba="0.470588 0.470588 0.470588 1.0"/>
</material>
</visual>
<collision>
<geometry>
<mesh filename="package://motor.stl"/>
</geometry>
<material name="platesblock_3_1_motor_material">
<color rgba="0.470588 0.470588 0.470588 1.0"/>
</material>
</collision>
<inertial>
<origin xyz="2.21444e-09 -0.00683721 0.000497669" rpy="0 0 0"/>
<mass value="0.0171001"/>
<inertia ixx="2.29537e-06" ixy="-5.64962e-13"  ixz="-2.154e-13" iyy="1.52616e-06" iyz="-6.36265e-08" izz="2.01963e-06" />
</inertial>
</link>
<joint name="platesblock_3_platesblock_3_1_motor_fixing" type="fixed">
<origin xyz="-0.063 -1.38951e-15 0.015" rpy="-4.20093e-15 8.23833e-16 1.5708" />
<parent link="platesblock_3" />
<child link="platesblock_3_1_motor" />
<axis xyz="0 0 0"/>
</joint>

<link name="platesblock_3_2_motor">
<visual>
<geometry>
<mesh filename="package://motor.stl"/>
</geometry>
<material name="platesblock_3_2_motor_material">
<color rgba="0.470588 0.470588 0.470588 1.0"/>
</material>
</visual>
<collision>
<geometry>
<mesh filename="package://motor.stl"/>
</geometry>
<material name="platesblock_3_2_motor_material">
<color rgba="0.470588 0.470588 0.470588 1.0"/>
</material>
</collision>
<inertial>
<origin xyz="2.21444e-09 -0.00683721 0.000497669" rpy="0 0 0"/>
<mass value="0.0171001"/>
<inertia ixx="2.29537e-06" ixy="-5.64962e-13"  ixz="-2.154e-13" iyy="1.52616e-06" iyz="-6.36265e-08" izz="2.01963e-06" />
</inertial>
</link>
<joint name="platesblock_3_platesblock_3_2_motor_fixing" type="fixed">
<origin xyz="0 0 0.015" rpy="2.27655e-15 -8.23833e-16 -1.5708" />
<parent link="platesblock_3" />
<child link="platesblock_3_2_motor" />
<axis xyz="0 0 0"/>
</joint>

<link name="platesblock_3_3_horn">
<visual>
<geometry>
<mesh filename="package://horn.stl"/>
</geometry>
<material name="platesblock_3_3_horn_material">
<color rgba="0.917647 0.917647 0.917647 1.0"/>
</material>
</visual>
<collision>
<geometry>
<mesh filename="package://horn.stl"/>
</geometry>
<material name="platesblock_3_3_horn_material">
<color rgba="0.917647 0.917647 0.917647 1.0"/>
</material>
</collision>
<inertial>
<origin xyz="-2.29324e-19 -1.05216e-18 -0.0134483" rpy="0 0 0"/>
<mass value="0.000575062"/>
<inertia ixx="1.30173e-08" ixy="0"  ixz="0" iyy="1.30173e-08" iyz="0" izz="2.51949e-08" />
</inertial>
</link>
<joint name="platesblock_3_platesblock_3_3_horn_fixing" type="fixed">
<origin xyz="-0.063 -1.38951e-15 0.015" rpy="2.08789e-15 5.89382e-16 3.06435" />
<parent link="platesblock_3" />
<child link="platesblock_3_3_horn" />
<axis xyz="0 0 0"/>
</joint>

<link name="platesblock_3_4_plate">
<visual>
<geometry>
<mesh filename="package://plate.stl"/>
</geometry>
<material name="platesblock_3_4_plate_material">
<color rgba="0.972549 0.529412 0.00392157 1.0"/>
</material>
</visual>
<collision>
<geometry>
<mesh filename="package://plate.stl"/>
</geometry>
<material name="platesblock_3_4_plate_material">
<color rgba="0.972549 0.529412 0.00392157 1.0"/>
</material>
</collision>
<inertial>
<origin xyz="0.0375 -1.298e-18 0.00115" rpy="0 0 0"/>
<mass value="0.00321261"/>
<inertia ixx="1.09131e-07" ixy="0"  ixz="0" iyy="1.41928e-06" iyz="0" izz="1.52558e-06" />
</inertial>
</link>
<joint name="platesblock_3_platesblock_3_4_plate_fixing" type="fixed">
<origin xyz="0.006 -0.0143 0.015" rpy="1.5708 2.85734e-15 -3.14159" />
<parent link="platesblock_3" />
<child link="platesblock_3_4_plate" />
<axis xyz="0 0 0"/>
</joint>

<link name="platesblock_3_5_horn">
<visual>
<geometry>
<mesh filename="package://horn.stl"/>
</geometry>
<material name="platesblock_3_5_horn_material">
<color rgba="0.917647 0.917647 0.917647 1.0"/>
</material>
</visual>
<collision>
<geometry>
<mesh filename="package://horn.stl"/>
</geometry>
<material name="platesblock_3_5_horn_material">
<color rgba="0.917647 0.917647 0.917647 1.0"/>
</material>
</collision>
<inertial>
<origin xyz="-2.29324e-19 -1.05216e-18 -0.0134483" rpy="0 0 0"/>
<mass value="0.000575062"/>
<inertia ixx="1.30173e-08" ixy="0"  ixz="0" iyy="1.30173e-08" iyz="0" izz="2.51949e-08" />
</inertial>
</link>
<joint name="platesblock_3_platesblock_3_5_horn_fixing" type="fixed">
<origin xyz="0 1.73472e-18 0.015" rpy="-1.37343e-32 -2.07301e-31 6.05673e-33" />
<parent link="platesblock_3" />
<child link="platesblock_3_5_horn" />
<axis xyz="0 0 0"/>
</joint>

<link name="hornside_3">
<inertial>
<origin xyz="0 0 0" rpy="0 0 0" />
<mass value="1e-9" />
<inertia ixx="0" ixy="0" ixz="0" iyy="0" iyz="0" izz="0" />
</inertial>
</link>
<link name="hornside_3_0_horntobottom">
<visual>
<geometry>
<mesh filename="package://horntobottom.stl"/>
</geometry>
<material name="hornside_3_0_horntobottom_material">
<color rgba="0.972549 0.529412 0.00392157 1.0"/>
</material>
</visual>
<collision>
<geometry>
<mesh filename="package://horntobottom.stl"/>
</geometry>
<material name="hornside_3_0_horntobottom_material">
<color rgba="0.972549 0.529412 0.00392157 1.0"/>
</material>
</collision>
<inertial>
<origin xyz="-4.74942e-15 0.0245577 0.0157805" rpy="0 0 0"/>
<mass value="0.00214736"/>
<inertia ixx="6.93961e-07" ixy="0"  ixz="0" iyy="8.42583e-08" iyz="1.70989e-08" izz="7.72522e-07" />
</inertial>
</link>
<joint name="hornside_3_hornside_3_0_horntobottom_fixing" type="fixed">
<origin xyz="2.61943e-16 1.38778e-16 -0.015" rpy="3.14159 1.57273e-15 -3.14159" />
<parent link="hornside_3" />
<child link="hornside_3_0_horntobottom" />
<axis xyz="0 0 0"/>
</joint>

<link name="hornside_3_1_motor">
<visual>
<geometry>
<mesh filename="package://motor.stl"/>
</geometry>
<material name="hornside_3_1_motor_material">
<color rgba="0.470588 0.470588 0.470588 1.0"/>
</material>
</visual>
<collision>
<geometry>
<mesh filename="package://motor.stl"/>
</geometry>
<material name="hornside_3_1_motor_material">
<color rgba="0.470588 0.470588 0.470588 1.0"/>
</material>
</collision>
<inertial>
<origin xyz="2.21444e-09 -0.00683721 0.000497669" rpy="0 0 0"/>
<mass value="0.0171001"/>
<inertia ixx="2.29537e-06" ixy="-5.64962e-13"  ixz="-2.154e-13" iyy="1.52616e-06" iyz="-6.36265e-08" izz="2.01963e-06" />
</inertial>
</link>
<joint name="hornside_3_hornside_3_1_motor_fixing" type="fixed">
<origin xyz="9.36751e-17 0.071 -0.015" rpy="-3.14159 1.6901e-15 -3.14159" />
<parent link="hornside_3" />
<child link="hornside_3_1_motor" />
<axis xyz="0 0 0"/>
</joint>

<link name="hornside_3_2_horntobottom">
<visual>
<geometry>
<mesh filename="package://horntobottom.stl"/>
</geometry>
<material name="hornside_3_2_horntobottom_material">
<color rgba="0.972549 0.529412 0.00392157 1.0"/>
</material>
</visual>
<collision>
<geometry>
<mesh filename="package://horntobottom.stl"/>
</geometry>
<material name="hornside_3_2_horntobottom_material">
<color rgba="0.972549 0.529412 0.00392157 1.0"/>
</material>
</collision>
<inertial>
<origin xyz="-4.74942e-15 0.0245577 0.0157805" rpy="0 0 0"/>
<mass value="0.00214736"/>
<inertia ixx="6.93961e-07" ixy="0"  ixz="0" iyy="8.42583e-08" iyz="1.70989e-08" izz="7.72522e-07" />
</inertial>
</link>
<joint name="hornside_3_hornside_3_2_horntobottom_fixing" type="fixed">
<origin xyz="0 0 -0.015" rpy="1.3705e-31 -5.14029e-31 8.35027e-33" />
<parent link="hornside_3" />
<child link="hornside_3_2_horntobottom" />
<axis xyz="0 0 0"/>
</joint>

<link name="hornside_3_3_horn">
<visual>
<geometry>
<mesh filename="package://horn.stl"/>
</geometry>
<material name="hornside_3_3_horn_material">
<color rgba="0.917647 0.917647 0.917647 1.0"/>
</material>
</visual>
<collision>
<geometry>
<mesh filename="package://horn.stl"/>
</geometry>
<material name="hornside_3_3_horn_material">
<color rgba="0.917647 0.917647 0.917647 1.0"/>
</material>
</collision>
<inertial>
<origin xyz="-2.29324e-19 -1.05216e-18 -0.0134483" rpy="0 0 0"/>
<mass value="0.000575062"/>
<inertia ixx="1.30173e-08" ixy="0"  ixz="0" iyy="1.30173e-08" iyz="0" izz="2.51949e-08" />
</inertial>
</link>
<joint name="hornside_3_hornside_3_3_horn_fixing" type="fixed">
<origin xyz="9.36751e-17 0.071 -0.015" rpy="-3.14159 3.45038e-16 -2.97494e-15" />
<parent link="hornside_3" />
<child link="hornside_3_3_horn" />
<axis xyz="0 0 0"/>
</joint>

<link name="leg_3">
<inertial>
<origin xyz="0 0 0" rpy="0 0 0" />
<mass value="1e-9" />
<inertia ixx="0" ixy="0" ixz="0" iyy="0" iyz="0" izz="0" />
</inertial>
</link>
<link name="leg_3_0_leg">
<visual>
<geometry>
<mesh filename="package://leg.stl"/>
</geometry>
<material name="leg_3_0_leg_material">
<color rgba="0.972549 0.529412 0.00392157 1.0"/>
</material>
</visual>
<collision>
<geometry>
<mesh filename="package://leg.stl"/>
</geometry>
<material name="leg_3_0_leg_material">
<color rgba="0.972549 0.529412 0.00392157 1.0"/>
</material>
</collision>
<inertial>
<origin xyz="-2.58551e-17 -1.31238e-17 -0.0546998" rpy="0 0 0"/>
<mass value="0.0151258"/>
<inertia ixx="1.99013e-05" ixy="0"  ixz="0" iyy="1.74063e-05" iyz="0" izz="3.49853e-06" />
</inertial>
</link>
<joint name="leg_3_leg_3_0_leg_fixing" type="fixed">
<origin xyz="0 0.015 0" rpy="-3.17402e-32 1.05198e-32 -1.46592e-31" />
<parent link="leg_3" />
<child link="leg_3_0_leg" />
<axis xyz="0 0 0"/>
</joint>

<joint name="leg3_d" type="revolute">
<origin xyz="9.36751e-17 0.071 1.5439e-16" rpy="-1.5708 -3.41689e-16 -3.14159" />
<parent link="hornside_3" />
<child link="leg_3" />
<axis xyz="0 1 0"/>
<limit effort="1.5" velocity="22" />
<joint_properties friction="0.0"/>
</joint>

<joint name="leg3_c" type="revolute">
<origin xyz="-0.063 -1.42074e-15 2.60209e-17" rpy="3.14159 -1.78551e-15 -1.5708" />
<parent link="platesblock_3" />
<child link="hornside_3" />
<axis xyz="0 0 -1"/>
<limit effort="1.5" velocity="22" />
<joint_properties friction="0.0"/>
</joint>

<joint name="leg3_b" type="revolute">
<origin xyz="-0.015 0.015 0.0406" rpy="-2.85964e-16 1.5708 0" />
<parent link="doubleu_3" />
<child link="platesblock_3" />
<axis xyz="0 0 1"/>
<limit effort="1.5" velocity="22" />
<joint_properties friction="0.0"/>
</joint>

<joint name="leg3_a" type="revolute">
<origin xyz="0.0485 1.12965e-17 -0.0007" rpy="1.5708 7.94086e-23 1.5708" />
<parent link="body_1" />
<child link="doubleu_3" />
<axis xyz="0 1 0"/>
<limit effort="1.5" velocity="22" />
<joint_properties friction="0.0"/>
</joint>

<link name="doubleu_4">
<inertial>
<origin xyz="0 0 0" rpy="0 0 0" />
<mass value="1e-9" />
<inertia ixx="0" ixy="0" ixz="0" iyy="0" iyz="0" izz="0" />
</inertial>
</link>
<link name="doubleu_4_0_u">
<visual>
<geometry>
<mesh filename="package://u.stl"/>
</geometry>
<material name="doubleu_4_0_u_material">
<color rgba="0.972549 0.529412 0.00392157 1.0"/>
</material>
</visual>
<collision>
<geometry>
<mesh filename="package://u.stl"/>
</geometry>
<material name="doubleu_4_0_u_material">
<color rgba="0.972549 0.529412 0.00392157 1.0"/>
</material>
</collision>
<inertial>
<origin xyz="3.08295e-18 4.6092e-18 -0.00844242" rpy="0 0 0"/>
<mass value="0.00415349"/>
<inertia ixx="1.25185e-06" ixy="0"  ixz="0" iyy="5.73141e-07" iyz="0" izz="9.62751e-07" />
</inertial>
</link>
<joint name="doubleu_4_doubleu_4_0_u_fixing" type="fixed">
<origin xyz="6.16298e-33 0.015 0.018" rpy="0 -0 -3.2608e-31" />
<parent link="doubleu_4" />
<child link="doubleu_4_0_u" />
<axis xyz="0 0 0"/>
</joint>

<link name="doubleu_4_1_u">
<visual>
<geometry>
<mesh filename="package://u.stl"/>
</geometry>
<material name="doubleu_4_1_u_material">
<color rgba="0.972549 0.529412 0.00392157 1.0"/>
</material>
</visual>
<collision>
<geometry>
<mesh filename="package://u.stl"/>
</geometry>
<material name="doubleu_4_1_u_material">
<color rgba="0.972549 0.529412 0.00392157 1.0"/>
</material>
</collision>
<inertial>
<origin xyz="3.08295e-18 4.6092e-18 -0.00844242" rpy="0 0 0"/>
<mass value="0.00415349"/>
<inertia ixx="1.25185e-06" ixy="0"  ixz="0" iyy="5.73141e-07" iyz="0" izz="9.62751e-07" />
</inertial>
</link>
<joint name="doubleu_4_doubleu_4_1_u_fixing" type="fixed">
<origin xyz="9.11743e-17 0.015 0.0226" rpy="-3.14159 -7.93809e-15 1.5708" />
<parent link="doubleu_4" />
<child link="doubleu_4_1_u" />
<axis xyz="0 0 0"/>
</joint>

<link name="platesblock_4">
<inertial>
<origin xyz="0 0 0" rpy="0 0 0" />
<mass value="1e-9" />
<inertia ixx="0" ixy="0" ixz="0" iyy="0" iyz="0" izz="0" />
</inertial>
</link>
<link name="platesblock_4_0_plate">
<visual>
<geometry>
<mesh filename="package://plate.stl"/>
</geometry>
<material name="platesblock_4_0_plate_material">
<color rgba="0.972549 0.529412 0.00392157 1.0"/>
</material>
</visual>
<collision>
<geometry>
<mesh filename="package://plate.stl"/>
</geometry>
<material name="platesblock_4_0_plate_material">
<color rgba="0.972549 0.529412 0.00392157 1.0"/>
</material>
</collision>
<inertial>
<origin xyz="0.0375 -1.298e-18 0.00115" rpy="0 0 0"/>
<mass value="0.00321261"/>
<inertia ixx="1.09131e-07" ixy="0"  ixz="0" iyy="1.41928e-06" iyz="0" izz="1.52558e-06" />
</inertial>
</link>
<joint name="platesblock_4_platesblock_4_0_plate_fixing" type="fixed">
<origin xyz="0.006 0.012 0.0135" rpy="1.5708 1.00918e-15 -3.14159" />
<parent link="platesblock_4" />
<child link="platesblock_4_0_plate" />
<axis xyz="0 0 0"/>
</joint>

<link name="platesblock_4_1_plate">
<visual>
<geometry>
<mesh filename="package://plate.stl"/>
</geometry>
<material name="platesblock_4_1_plate_material">
<color rgba="0.972549 0.529412 0.00392157 1.0"/>
</material>
</visual>
<collision>
<geometry>
<mesh filename="package://plate.stl"/>
</geometry>
<material name="platesblock_4_1_plate_material">
<color rgba="0.972549 0.529412 0.00392157 1.0"/>
</material>
</collision>
<inertial>
<origin xyz="0.0375 -1.298e-18 0.00115" rpy="0 0 0"/>
<mass value="0.00321261"/>
<inertia ixx="1.09131e-07" ixy="0"  ixz="0" iyy="1.41928e-06" iyz="0" izz="1.52558e-06" />
</inertial>
</link>
<joint name="platesblock_4_platesblock_4_1_plate_fixing" type="fixed">
<origin xyz="0.006 -0.0143 0.0135" rpy="1.5708 -3.34319e-16 -3.14159" />
<parent link="platesblock_4" />
<child link="platesblock_4_1_plate" />
<axis xyz="0 0 0"/>
</joint>

<link name="platesblock_4_2_horn">
<visual>
<geometry>
<mesh filename="package://horn.stl"/>
</geometry>
<material name="platesblock_4_2_horn_material">
<color rgba="0.917647 0.917647 0.917647 1.0"/>
</material>
</visual>
<collision>
<geometry>
<mesh filename="package://horn.stl"/>
</geometry>
<material name="platesblock_4_2_horn_material">
<color rgba="0.917647 0.917647 0.917647 1.0"/>
</material>
</collision>
<inertial>
<origin xyz="-2.29324e-19 -1.05216e-18 -0.0134483" rpy="0 0 0"/>
<mass value="0.000575062"/>
<inertia ixx="1.30173e-08" ixy="0"  ixz="0" iyy="1.30173e-08" iyz="0" izz="2.51949e-08" />
</inertial>
</link>
<joint name="platesblock_4_platesblock_4_2_horn_fixing" type="fixed">
<origin xyz="0 0 0.0135" rpy="2.10821e-32 -1.54087e-32 3.19062e-32" />
<parent link="platesblock_4" />
<child link="platesblock_4_2_horn" />
<axis xyz="0 0 0"/>
</joint>

<link name="platesblock_4_3_horn">
<visual>
<geometry>
<mesh filename="package://horn.stl"/>
</geometry>
<material name="platesblock_4_3_horn_material">
<color rgba="0.917647 0.917647 0.917647 1.0"/>
</material>
</visual>
<collision>
<geometry>
<mesh filename="package://horn.stl"/>
</geometry>
<material name="platesblock_4_3_horn_material">
<color rgba="0.917647 0.917647 0.917647 1.0"/>
</material>
</collision>
<inertial>
<origin xyz="-2.29324e-19 -1.05216e-18 -0.0134483" rpy="0 0 0"/>
<mass value="0.000575062"/>
<inertia ixx="1.30173e-08" ixy="0"  ixz="0" iyy="1.30173e-08" iyz="0" izz="2.51949e-08" />
</inertial>
</link>
<joint name="platesblock_4_platesblock_4_3_horn_fixing" type="fixed">
<origin xyz="-0.063 -1.59421e-15 0.0135" rpy="1.40873e-16 1.2058e-15 -3.14159" />
<parent link="platesblock_4" />
<child link="platesblock_4_3_horn" />
<axis xyz="0 0 0"/>
</joint>

<link name="platesblock_4_4_motor">
<visual>
<geometry>
<mesh filename="package://motor.stl"/>
</geometry>
<material name="platesblock_4_4_motor_material">
<color rgba="0.470588 0.470588 0.470588 1.0"/>
</material>
</visual>
<collision>
<geometry>
<mesh filename="package://motor.stl"/>
</geometry>
<material name="platesblock_4_4_motor_material">
<color rgba="0.470588 0.470588 0.470588 1.0"/>
</material>
</collision>
<inertial>
<origin xyz="2.21444e-09 -0.00683721 0.000497669" rpy="0 0 0"/>
<mass value="0.0171001"/>
<inertia ixx="2.29537e-06" ixy="-5.64962e-13"  ixz="-2.154e-13" iyy="1.52616e-06" iyz="-6.36265e-08" izz="2.01963e-06" />
</inertial>
</link>
<joint name="platesblock_4_platesblock_4_4_motor_fixing" type="fixed">
<origin xyz="-1.38778e-17 0 0.0135" rpy="-7.89845e-16 -1.92615e-15 -1.5708" />
<parent link="platesblock_4" />
<child link="platesblock_4_4_motor" />
<axis xyz="0 0 0"/>
</joint>

<link name="platesblock_4_5_motor">
<visual>
<geometry>
<mesh filename="package://motor.stl"/>
</geometry>
<material name="platesblock_4_5_motor_material">
<color rgba="0.470588 0.470588 0.470588 1.0"/>
</material>
</visual>
<collision>
<geometry>
<mesh filename="package://motor.stl"/>
</geometry>
<material name="platesblock_4_5_motor_material">
<color rgba="0.470588 0.470588 0.470588 1.0"/>
</material>
</collision>
<inertial>
<origin xyz="2.21444e-09 -0.00683721 0.000497669" rpy="0 0 0"/>
<mass value="0.0171001"/>
<inertia ixx="2.29537e-06" ixy="-5.64962e-13"  ixz="-2.154e-13" iyy="1.52616e-06" iyz="-6.36265e-08" izz="2.01963e-06" />
</inertial>
</link>
<joint name="platesblock_4_platesblock_4_5_motor_fixing" type="fixed">
<origin xyz="-0.063 -1.59248e-15 0.0135" rpy="2.88575e-15 1.92615e-15 1.5708" />
<parent link="platesblock_4" />
<child link="platesblock_4_5_motor" />
<axis xyz="0 0 0"/>
</joint>

<link name="hornside_4">
<inertial>
<origin xyz="0 0 0" rpy="0 0 0" />
<mass value="1e-9" />
<inertia ixx="0" ixy="0" ixz="0" iyy="0" iyz="0" izz="0" />
</inertial>
</link>
<link name="hornside_4_0_horntobottom">
<visual>
<geometry>
<mesh filename="package://horntobottom.stl"/>
</geometry>
<material name="hornside_4_0_horntobottom_material">
<color rgba="0.972549 0.529412 0.00392157 1.0"/>
</material>
</visual>
<collision>
<geometry>
<mesh filename="package://horntobottom.stl"/>
</geometry>
<material name="hornside_4_0_horntobottom_material">
<color rgba="0.972549 0.529412 0.00392157 1.0"/>
</material>
</collision>
<inertial>
<origin xyz="-4.74942e-15 0.0245577 0.0157805" rpy="0 0 0"/>
<mass value="0.00214736"/>
<inertia ixx="6.93961e-07" ixy="0"  ixz="0" iyy="8.42583e-08" iyz="1.70989e-08" izz="7.72522e-07" />
</inertial>
</link>
<joint name="hornside_4_hornside_4_0_horntobottom_fixing" type="fixed">
<origin xyz="2.96638e-16 -3.05311e-16 -0.015" rpy="3.14159 -8.32667e-17 3.14159" />
<parent link="hornside_4" />
<child link="hornside_4_0_horntobottom" />
<axis xyz="0 0 0"/>
</joint>

<link name="hornside_4_1_horntobottom">
<visual>
<geometry>
<mesh filename="package://horntobottom.stl"/>
</geometry>
<material name="hornside_4_1_horntobottom_material">
<color rgba="0.972549 0.529412 0.00392157 1.0"/>
</material>
</visual>
<collision>
<geometry>
<mesh filename="package://horntobottom.stl"/>
</geometry>
<material name="hornside_4_1_horntobottom_material">
<color rgba="0.972549 0.529412 0.00392157 1.0"/>
</material>
</collision>
<inertial>
<origin xyz="-4.74942e-15 0.0245577 0.0157805" rpy="0 0 0"/>
<mass value="0.00214736"/>
<inertia ixx="6.93961e-07" ixy="0"  ixz="0" iyy="8.42583e-08" iyz="1.70989e-08" izz="7.72522e-07" />
</inertial>
</link>
<joint name="hornside_4_hornside_4_1_horntobottom_fixing" type="fixed">
<origin xyz="-1.73472e-18 0 -0.015" rpy="2.95607e-31 -1.62454e-31 4.65205e-32" />
<parent link="hornside_4" />
<child link="hornside_4_1_horntobottom" />
<axis xyz="0 0 0"/>
</joint>

<link name="hornside_4_2_horn">
<visual>
<geometry>
<mesh filename="package://horn.stl"/>
</geometry>
<material name="hornside_4_2_horn_material">
<color rgba="0.917647 0.917647 0.917647 1.0"/>
</material>
</visual>
<collision>
<geometry>
<mesh filename="package://horn.stl"/>
</geometry>
<material name="hornside_4_2_horn_material">
<color rgba="0.917647 0.917647 0.917647 1.0"/>
</material>
</collision>
<inertial>
<origin xyz="-2.29324e-19 -1.05216e-18 -0.0134483" rpy="0 0 0"/>
<mass value="0.000575062"/>
<inertia ixx="1.30173e-08" ixy="0"  ixz="0" iyy="1.30173e-08" iyz="0" izz="2.51949e-08" />
</inertial>
</link>
<joint name="hornside_4_hornside_4_2_horn_fixing" type="fixed">
<origin xyz="1.249e-16 0.071 -0.015" rpy="3.14159 5.21657e-15 -1.5708" />
<parent link="hornside_4" />
<child link="hornside_4_2_horn" />
<axis xyz="0 0 0"/>
</joint>

<link name="hornside_4_3_motor">
<visual>
<geometry>
<mesh filename="package://motor.stl"/>
</geometry>
<material name="hornside_4_3_motor_material">
<color rgba="0.470588 0.470588 0.470588 1.0"/>
</material>
</visual>
<collision>
<geometry>
<mesh filename="package://motor.stl"/>
</geometry>
<material name="hornside_4_3_motor_material">
<color rgba="0.470588 0.470588 0.470588 1.0"/>
</material>
</collision>
<inertial>
<origin xyz="2.21444e-09 -0.00683721 0.000497669" rpy="0 0 0"/>
<mass value="0.0171001"/>
<inertia ixx="2.29537e-06" ixy="-5.64962e-13"  ixz="-2.154e-13" iyy="1.52616e-06" iyz="-6.36265e-08" izz="2.01963e-06" />
</inertial>
</link>
<joint name="hornside_4_hornside_4_3_motor_fixing" type="fixed">
<origin xyz="1.249e-16 0.071 -0.015" rpy="3.14159 -3.89784e-30 3.14159" />
<parent link="hornside_4" />
<child link="hornside_4_3_motor" />
<axis xyz="0 0 0"/>
</joint>

<link name="leg_4">
<inertial>
<origin xyz="0 0 0" rpy="0 0 0" />
<mass value="1e-9" />
<inertia ixx="0" ixy="0" ixz="0" iyy="0" iyz="0" izz="0" />
</inertial>
</link>
<link name="leg_4_0_leg">
<visual>
<geometry>
<mesh filename="package://leg.stl"/>
</geometry>
<material name="leg_4_0_leg_material">
<color rgba="0.972549 0.529412 0.00392157 1.0"/>
</material>
</visual>
<collision>
<geometry>
<mesh filename="package://leg.stl"/>
</geometry>
<material name="leg_4_0_leg_material">
<color rgba="0.972549 0.529412 0.00392157 1.0"/>
</material>
</collision>
<inertial>
<origin xyz="-2.58551e-17 -1.31238e-17 -0.0546998" rpy="0 0 0"/>
<mass value="0.0151258"/>
<inertia ixx="1.99013e-05" ixy="0"  ixz="0" iyy="1.74063e-05" iyz="0" izz="3.49853e-06" />
</inertial>
</link>
<joint name="leg_4_leg_4_0_leg_fixing" type="fixed">
<origin xyz="0 -0.015 0" rpy="-5.51365e-32 -2.23367e-33 1.42588e-31" />
<parent link="leg_4" />
<child link="leg_4_0_leg" />
<axis xyz="0 0 0"/>
</joint>

<joint name="leg4_d" type="revolute">
<origin xyz="7.97973e-17 0.071 2.98372e-16" rpy="1.5708 1.03256e-16 -1.45299e-15" />
<parent link="hornside_4" />
<child link="leg_4" />
<axis xyz="0 -1 0"/>
<limit effort="1.5" velocity="22" />
<joint_properties friction="0.0"/>
</joint>

<joint name="leg4_c" type="revolute">
<origin xyz="-0.063 -1.59421e-15 -0.0015" rpy="3.14159 3.17592e-15 -1.5708" />
<parent link="platesblock_4" />
<child link="hornside_4" />
<axis xyz="0 0 -1"/>
<limit effort="1.5" velocity="22" />
<joint_properties friction="0.0"/>
</joint>

<joint name="leg4_b" type="revolute">
<origin xyz="-0.015 0.015 0.0406" rpy="-4.23049e-15 1.5708 0" />
<parent link="doubleu_4" />
<child link="platesblock_4" />
<axis xyz="0 0 1"/>
<limit effort="1.5" velocity="22" />
<joint_properties friction="0.0"/>
</joint>

<joint name="leg4_a" type="revolute">
<origin xyz="3.55237e-17 0.0485 -0.0007" rpy="1.5708 3.85179e-15 -3.14159" />
<parent link="body_1" />
<child link="doubleu_4" />
<axis xyz="0 1 0"/>
<limit effort="1.5" velocity="22" />
<joint_properties friction="0.0"/>
</joint>

</robot>
